<?xml version="1.0" encoding="utf-8"?>
<!-- =================================================================================== -->
<!-- |    This document was autogenerated by xacro from platform.urdf.xacro            | -->
<!-- |    EDITING THIS FILE BY HAND IS NOT RECOMMENDED                                 | -->
<!-- =================================================================================== -->
<robot name="platform" xmlns:xacro="http://www.ros.org/wiki/xacro">
  <!-- P0 -->
  <link name="p0_link">
    <inertial>
      <mass value="100.0"/>
      <origin xyz="0.0 0.0 0.1375"/>
      <inertia ixx="640208333.333333" ixy="0" ixz="0" iyy="640208333.333333" iyz="0" izz="20000000"/>
    </inertial>
    <visual>
      <origin rpy="0 0 0" xyz="0.0 0.0 0.1375"/>
      <geometry>
        <cylinder length="0.275" radius="0.02"/>
      </geometry>
      <material name="Black">
        <color rgba="0 0 0 1.0"/>
      </material>
    </visual>
    <collision>
      <origin rpy="0.0 0.0 0.0" xyz="0.0 0.0 0.1375"/>
      <geometry>
        <cylinder length="0.275" radius="0.02"/>
      </geometry>
    </collision>
  </link>
  <gazebo reference="p0_link">
    <material>Gazebo/Yellow</material>
    <selfCollide>true</selfCollide>
  </gazebo>
  <!-- P1 -->
  <link name="p1_link">
    <inertial>
      <mass value="100.0"/>
      <origin xyz="0.0 0.0 0.0"/>
      <inertia ixx="640208333.333333" ixy="0" ixz="0" iyy="640208333.333333" iyz="0" izz="20000000"/>
    </inertial>
    <visual>
      <origin xyz="0.0 0.0 0.0" rpy="0 0 0" />
      <geometry>
        <cylinder radius="${leg_radius}" length="0.0" />
      </geometry>
      <material name="Black">
		<color rgba="0 0 0 1.0"/>
      </material>
    </visual> 
    <collision>
      <origin xyz="0.0 0.0 0.0" rpy="0.0 0.0 0.0" />
      <geometry>
        <cylinder radius="${leg_radius}" length="0.0" />
      </geometry>
    </collision>
  </link>
  <gazebo reference="p1_link">
    <material>Gazebo/Green</material>
    <selfCollide>true</selfCollide>
  </gazebo>
  <!-- p0_joint -->
  <joint name="p0_joint" type="revolute">
    <parent link="p0_link"/>
    <origin rpy="0 0 0" xyz="0.0 0.0 0.275"/>
    <child link="p1_link"/>
    <limit effort="1000.0" lower="-2.0" upper="2.0" velocity="1.5"/>
    <axis xyz="0 1 0"/>
  </joint>
  <!-- p0_transmission -->
  <transmission name="p0_transmission">
    <type>transmission_interface/SimpleTransmission</type>
    <joint name="p0_joint">
      <hardwareInterface>hardware_interface/PositionJointInterface</hardwareInterface>
    </joint>
    <actuator name="p0_motor">
      <hardwareInterface>hardware_interface/PositionJointInterface</hardwareInterface>
      <mechanicalReduction>1.0</mechanicalReduction>
    </actuator>
  </transmission>
  <!-- platformtop -->
  <link name="platform_top_link">
    <inertial>
      <mass value="1.0"/>
      <origin xyz="0.0 0.0 0.025"/>
      <inertia ixx="1" ixy="0" ixz="0" iyy="1" iyz="0" izz="1"/>
    </inertial>
    <visual>
      <origin xyz="0.0 0.0 0.025"/>
      <geometry>
        <cylinder length="0.05" radius="0.3"/>
      </geometry>
      <material name="Grey">
        <color rgba="0.65 0.65 0.65 1.0"/>
      </material>
    </visual>
    <collision>
      <origin xyz="0.0 0.0 0.025"/>
      <geometry>
        <cylinder length="0.05" radius="0.3"/>
      </geometry>
    </collision>
  </link>
  <gazebo reference="platform_top_link">
    <material>Gazebo/Red</material>
    <selfCollide>true</selfCollide>
  </gazebo>
  <!-- p1_joint -->
  <joint name="p1_joint" type="revolute">
    <parent link="p1_link"/>
    <origin rpy="0 0 0" xyz="0.0 0.0 0.0"/>
    <child link="platform_top_link"/>
    <limit effort="1000.0" lower="-2.0" upper="2.0" velocity="1.5"/>
    <axis xyz="1 0 0"/>
  </joint>
  <!-- p1_transmission -->
  <transmission name="p1_transmission">
    <type>transmission_interface/SimpleTransmission</type>
    <joint name="p1_joint">
      <hardwareInterface>hardware_interface/PositionJointInterface</hardwareInterface>
    </joint>
    <actuator name="p1_motor">
      <hardwareInterface>hardware_interface/PositionJointInterface</hardwareInterface>
      <mechanicalReduction>1.0</mechanicalReduction>
    </actuator>
  </transmission>
  <!-- IMU -->
  <link name="imu_link">
    <inertial>
      <mass value="0.001"/>
      <origin rpy="0.0 0.0 0.0" xyz="0 0 0"/>
      <inertia ixx="0.0001" ixy="0" ixz="0" iyy="0.000001" iyz="0" izz="0.0001"/>
    </inertial>
    <visual>
      <origin rpy="0 0 0" xyz="0 0 0"/>
      <geometry>
        <box size="0.01 0.01 0.01"/>
      </geometry>
    </visual>
    <collision>
      <origin rpy="0 0 0" xyz="0 0 0"/>
      <geometry>
        <box size=".001 .001 .001"/>
      </geometry>
    </collision>
  </link>
  <gazebo reference="imu_link">
    <material>Gazebo/Green</material>
  </gazebo>
  <!-- IMU joint -->
  <joint name="imu_joint" type="fixed">
    <axis xyz="1 0 0"/>
    <!-- 0 1 0 -->
    <origin xyz="0 0 0.0"/>
    <parent link="platform_top_link"/>
    <child link="imu_link"/>
  </joint>
  <!-- The imu sensor -->
  <gazebo reference="imu_link">
    <gravity>true</gravity>
    <sensor name="imu_sensor" type="imu">
      <always_on>true</always_on>
      <visualize>true</visualize>
      <plugin filename="libgazebo_ros_imu_sensor.so" name="imu_plugin">
        <topicName>/imu/data</topicName>
        <bodyName>imu_link</bodyName>
        <updateRateHZ>1000.0</updateRateHZ>
        <gaussianNoise>0.0</gaussianNoise>
        <xyzOffset>0 0 0</xyzOffset>
        <rpyOffset>0 0 0</rpyOffset>
        <frameName>imu_link</frameName>
      </plugin>
      <pose>0 0 0 0 0 0</pose>
    </sensor>
  </gazebo>
  <gazebo>
    <!--static>true</static-->
    <canonicalBody>p0_link</canonicalBody>
  </gazebo>
</robot>

