<?xml version="1.0" encoding="utf-8"?>
<!-- =================================================================================== -->
<!-- |    This document was autogenerated by xacro from wam_platform.urdf.xacro        | -->
<!-- |    EDITING THIS FILE BY HAND IS NOT RECOMMENDED                                 | -->
<!-- =================================================================================== -->
<robot name="wam" xmlns:xacro="http://www.ros.org/wiki/xacro">
  <link name="world"/>
  <!-- P0 -->
  <link name="p0_link">
    <inertial>
      <mass value="500.0"/>
      <origin rpy="1.57079632679 1.57079632679 0" xyz="0 0.1375 0"/>
      <inertia ixx="3.2010" ixy="0" ixz="0" iyy="3.2010" iyz="0" izz="0.1"/>
    </inertial>
    <visual>
      <origin rpy="1.57079632679 1.57079632679 0" xyz="0 0.1375 0"/>
      <geometry>
        <cylinder length="0.275" radius="0.02"/>
      </geometry>
      <material name="Black">
        <color rgba="0 0 0 1.0"/>
      </material>
    </visual>
    <collision>
      <origin rpy="1.57079632679 1.57079632679 0" xyz="0 0.1375 0"/>
      <geometry>
        <cylinder length="0.275" radius="0.02"/>
      </geometry>
    </collision>
  </link>
  <gazebo reference="p0_link">
    <material>Gazebo/Yellow</material>
    <mu1>1000.0</mu1>
    <mu2>1000.0</mu2>
    <kp>10000000.0</kp>
    <kd>1.0</kd>
    <selfCollide>true</selfCollide>
  </gazebo>
  <!-- P1 -->
  <link name="p1_link">
    <inertial>
      <mass value="500.0"/>
      <origin rpy="1.57079632679 0 1.57079632679" xyz="0 0 0"/>
      <inertia ixx="3.2010" ixy="0" ixz="0" iyy="3.2010" iyz="0" izz="0.1"/>
    </inertial>
  </link>
  <gazebo reference="p1_link">
    <material>Gazebo/Green</material>
    <mu1>1000.0</mu1>
    <mu2>1000.0</mu2>
    <kp>10000000.0</kp>
    <kd>1.0</kd>
    <selfCollide>true</selfCollide>
  </gazebo>
  <!-- p0_joint -->
  <joint name="p0_joint" type="revolute">
    <parent link="p0_link"/>
    <origin rpy="1.57079632679 0 1.57079632679" xyz="0 0.275 0"/>
    <child link="p1_link"/>
    <limit effort="100000.0" lower="-2.0" upper="2.0" velocity="1.5"/>
    <axis xyz="0 1 0"/>
  </joint>
  <!-- p0_transmission -->
  <transmission name="p0_transmission">
    <type>transmission_interface/SimpleTransmission</type>
    <joint name="p0_joint">
      <hardwareInterface>hardware_interface/PositionJointInterface</hardwareInterface>
    </joint>
    <actuator name="p0_motor">
      <hardwareInterface>hardware_interface/PositionJointInterface</hardwareInterface>
      <mechanicalReduction>1.0</mechanicalReduction>
    </actuator>
  </transmission>
  <!-- platform top -->
  <link name="platform_top_link">
    <inertial>
      <mass value="5.0"/>
      <origin rpy="1.57079632679 0 1.57079632679" xyz="0.025 0 0"/>
      <inertia ixx="1.0" ixy="0" ixz="0" iyy="1.0" iyz="0" izz="1.0"/>
    </inertial>
    <visual>
      <origin rpy="1.57079632679 0 1.57079632679" xyz="0.025 0 0"/>
      <geometry>
        <cylinder length="0.05" radius="0.3"/>
      </geometry>
      <material name="Grey">
        <color rgba="0.65 0.65 0.65 1.0"/>
      </material>
    </visual>
    <collision>
      <origin rpy="1.57079632679 0 1.57079632679" xyz="0.025 0 0"/>
      <geometry>
        <cylinder length="0.05" radius="0.3"/>
      </geometry>
    </collision>
  </link>
  <gazebo reference="platform_top_link">
    <material>Gazebo/Red</material>
    <mu1>50.0</mu1>
    <mu2>50.0</mu2>
    <kp>1000000.0</kp>
    <kd>1.0</kd>
    <selfCollide>true</selfCollide>
  </gazebo>
  <!-- p1_joint -->
  <joint name="p1_joint" type="revolute">
    <parent link="p1_link"/>
    <origin rpy="0 0 0" xyz="0.0 0.0 0.0"/>
    <child link="platform_top_link"/>
    <limit effort="100000.0" lower="-2.0" upper="2.0" velocity="1.5"/>
    <axis xyz="0 0 1"/>
  </joint>
  <!-- p1_transmission -->
  <transmission name="p1_transmission">
    <type>transmission_interface/SimpleTransmission</type>
    <joint name="p1_joint">
      <hardwareInterface>hardware_interface/PositionJointInterface</hardwareInterface>
    </joint>
    <actuator name="p1_motor">
      <hardwareInterface>hardware_interface/PositionJointInterface</hardwareInterface>
      <mechanicalReduction>1.0</mechanicalReduction>
    </actuator>
  </transmission>
  <!-- IMU -->
  <link name="imu_link">
    <inertial>
      <mass value="0.01"/>
      <origin rpy="0.0 0.0 0.0" xyz="0 0 0"/>
      <inertia ixx="0.00000077083" ixy="0" ixz="0" iyy="0.00000077083" iyz="0" izz="0.00000077083"/>
    </inertial>
    <visual>
      <origin rpy="0 0 0" xyz="0 0 0"/>
      <geometry>
        <box size="0.03 0.03 0.005"/>
      </geometry>
    </visual>
    <collision>
      <origin rpy="0 0 0" xyz="0 0 0"/>
      <geometry>
        <box size="0.03 0.03 0.005"/>
      </geometry>
    </collision>
  </link>
  <gazebo reference="imu_link">
    <material>Gazebo/Green</material>
  </gazebo>
  <!-- IMU joint -->
  <joint name="imu_joint" type="fixed">
    <axis xyz="1 0 0"/>
    <!-- 0 1 0 -->
    <origin rpy="0 0 0" xyz="0.0 -0.24 0.0525"/>
    <parent link="platform_top_link"/>
    <child link="imu_link"/>
  </joint>
  <!-- The imu sensor -->
  <gazebo reference="imu_link">
    <gravity>true</gravity>
    <sensor name="imu_sensor" type="imu">
      <always_on>true</always_on>
      <visualize>true</visualize>
      <plugin filename="libgazebo_ros_imu_sensor.so" name="imu_plugin">
        <topicName>/imu/data</topicName>
        <bodyName>imu_link</bodyName>
        <updateRateHZ>1000.0</updateRateHZ>
        <gaussianNoise>0.0</gaussianNoise>
        <xyzOffset>0 0 0</xyzOffset>
        <rpyOffset>0 0 1.0472</rpyOffset>
        <frameName>imu_link</frameName>
      </plugin>
      <pose>0 0 0 0 0 0</pose>
    </sensor>
  </gazebo>
  <gazebo>
    <!--static>true</static-->
    <canonicalBody>p0_link</canonicalBody>
  </gazebo>
  <joint name="world_platform_joint" type="fixed">
    <parent link="world"/>
    <child link="p0_link"/>
    <origin rpy="1.57079632679 0 1.57079632679" xyz="-0.0 -0.0 0.0"/>
  </joint>
  <link name="wam_origin"/>
  <link name="wam_link_footprint"/>
  <joint name="wam_link_footprint_joint" type="fixed">
    <origin rpy="0 0 0" xyz="0.0 0.0 0.0"/>
    <child link="wam_link_footprint"/>
    <parent link="wam_origin"/>
  </joint>
  <link name="wam_link_base"/>
  <joint name="wam_link_base_joint" type="fixed">
    <origin rpy="0 0 0" xyz="0.0 0.0 0.0"/>
    <child link="wam_link_base"/>
    <parent link="wam_origin"/>
  </joint>
  <!-- Just to debug link 0 inertial orientation -->
  <!--
	<link name="wam_link_0_inertial" />
	<joint name="wam_link_0_inertial_joint" type="fixed">
		<origin xyz="-0.14071720 -0.02017671 -0.26604706" rpy="${M_PI/2} 0 ${M_PI/2}"/>
		<child link="wam_link_0_inertial"/>
		<parent link="wam_link_0"/>
	</joint>
-->
  <link name="wam_link_0">
    <inertial>
      <!--
	Inertia parameters from Barrett Technology, Inc, WAM Arm Inertial
	Specifications, 2008, pages 9-10, Document: D1005, Version: AC.02

	Note that the AXES used to compute the parameters are ROTATED with
	respect to the frame axes:

	Inertial_X -> Frame Y
	Inertial_Y -> Frame Z
	Inertial_Z -> Frame_X
-->
      <mass value="9.97059584"/>
      <origin rpy="1.57079632679 0 1.57079632679" xyz="-0.14071720 -0.02017671 -0.26604706"/>
      <inertia ixx="0.10916849" ixy="0.00640270" ixz="0.02557874" iyy="0.18294303" iyz="0.00161433" izz="0.11760385"/>
    </inertial>
    <visual>
      <origin rpy="0 0 0" xyz="0 0 0"/>
      <geometry name="wam_link_0_visual">
        <mesh filename="package://wam_description/meshes/wambase.stl" scale="1.0 1.0 1.0"/>
      </geometry>
      <material name="LightGrey">
        <color rgba="0.75 0.75 0.75 1.0"/>
      </material>
    </visual>
    <collision>
      <origin rpy="0 0 0" xyz="0.0 0.0 0.0"/>
      <geometry name="wam_link_base_collision">
        <mesh filename="package://wam_description/meshes/wambase.stl" scale="1.0 1.0 1.0"/>
      </geometry>
      <contact_coefficients kd="1.0" kp="1000.0" mu="0"/>
    </collision>
  </link>
  <gazebo reference="wam_link_0">
    <selfCollide>true</selfCollide>
    <material>Gazebo/White</material>
  </gazebo>
  <joint name="wam_joint_0" type="fixed">
    <!--origin rpy="0 0 0" xyz="-0.060 -0.140 0.206"/-->
    <origin rpy="0 0 0" xyz="0.22 0.14 0.346"/>
    <child link="wam_link_0"/>
    <parent link="wam_link_base"/>
  </joint>
  <link name="wam_link_1">
    <inertial>
      <!--
	from Barrett Technology, Inc, WAM Arm Inertial Specifications, 2008,
	pages 11-12, Document: D1005, Version: AC.02
-->
      <mass value="10.76768767"/>
      <origin xyz="-0.00443422 0.12189039 -0.00066489"/>
      <inertia ixx="0.13488033" ixy="-0.00213041" ixz="-0.00012485" iyy="0.11328369" iyz="0.00068555" izz="0.09046330"/>
    </inertial>
    <visual>
      <origin rpy="1.57079632679 0 0" xyz="0.0 0.0 0.0"/>
      <geometry name="wam_link_1_visual">
        <mesh filename="package://wam_description/meshes/wam1.stl" scale="1.0 1.0 1.0"/>
      </geometry>
      <material name="Grey">
        <color rgba="0.75 0.75 0.75 1.0"/>
      </material>
    </visual>
    <collision>
      <origin rpy="1.57079632679 0 0" xyz="0.0 0.0 0.0"/>
      <geometry name="wam_j1_collision">
        <mesh filename="package://wam_description/meshes/wam1.stl" scale="1.0 1.0 1.0"/>
      </geometry>
      <!--
			<contact_coefficients kd="1.0" kp="1000.0" mu="0"/>
			-->
    </collision>
  </link>
  <gazebo reference="wam_link_1">
    <material>Gazebo/White</material>
    <selfCollide>true</selfCollide>
  </gazebo>
  <joint name="wam_joint_1" type="revolute">
    <parent link="wam_link_0"/>
    <child link="wam_link_1"/>
    <origin rpy="-1.57079632679 0 0" xyz="0.0 0.0 0.0"/>
    <axis xyz="0 -1 0"/>
    <!--
	from Barrett Technology, Inc, WAM Arm User's Manual, 2008, Document:
	D1001, Version: AH.00
	
	lower and upper limits: page 71
	velocity: page 17
	friction: page 71
	effort: cable limit (page 75) x reduction (page 68)
-->
    <limit effort="75.6" lower="-2.6" upper="2.6" velocity="2.0"/>
    <!--dynamics friction="${3.0/7}"/-->
  </joint>
  <transmission name="j1_transmission">
    <type>transmission_interface/SimpleTransmission</type>
    <joint name="wam_joint_1">
      <hardwareInterface>hardware_interface/EffortJointInterface</hardwareInterface>
    </joint>
    <actuator name="j1_motor">
      <mechanicalReduction>42.0</mechanicalReduction>
    </actuator>
  </transmission>
  <link name="wam_link_2">
    <inertial>
      <!--
	from Barrett Technology, Inc, WAM Arm Inertial Specifications, 2008,
	pages 13-14, Document: D1005, Version: AC.02

-->
      <mass value="3.87493756"/>
      <origin xyz="-0.00236983 0.03105614 0.01542114"/>
      <inertia ixx="0.02140958" ixy="0.00027172" ixz="0.00002461" iyy="0.01377875" iyz="-0.00181920" izz="0.01558906"/>
    </inertial>
    <visual>
      <origin rpy="0 0 0" xyz="0.0 0.0 0.0"/>
      <geometry name="wam_link_2_visual">
        <mesh filename="package://wam_description/meshes/wam2.stl" scale="1.0 1.0 1.0"/>
      </geometry>
      <material name="Grey">
        <color rgba="0.75 0.75 0.75 1.0"/>
      </material>
    </visual>
    <collision>
      <origin rpy="0 0 0" xyz="0.0 0.0 0.0"/>
      <geometry name="wam_link_2_collision">
        <mesh filename="package://wam_description/meshes/wam2.stl" scale="1.0 1.0 1.0"/>
      </geometry>
      <contact_coefficients kd="1.0" kp="1000.0" mu="0"/>
    </collision>
  </link>
  <gazebo reference="wam_link_2">
    <material>Gazebo/White</material>
    <selfCollide>true</selfCollide>
  </gazebo>
  <joint name="wam_joint_2" type="revolute">
    <parent link="wam_link_1"/>
    <child link="wam_link_2"/>
    <origin rpy="1.57079632679 0 0" xyz="0.0 0.0 0.0"/>
    <axis xyz="0 1 0"/>
    <!--
	from Barrett Technology, Inc, WAM Arm User's Manual, 2008, Document:
	D1001, Version: AH.00
	
	lower and upper limits: page 71
	velocity: page 17
	friction: page 71
	effort: cable limit (page 75) x reduction (page 68)
-->
    <limit effort="50.85" lower="-2.0" upper="2.0" velocity="2.0"/>
    <!--dynamics friction="${3.0/7}"/-->
  </joint>
  <transmission name="j2_transmission">
    <type>transmission_interface/SimpleTransmission</type>
    <joint name="wam_joint_2">
      <hardwareInterface>hardware_interface/EffortJointInterface</hardwareInterface>
    </joint>
    <actuator name="j2_motor">
      <mechanicalReduction>28.25</mechanicalReduction>
    </actuator>
  </transmission>
  <link name="wam_link_3">
    <inertial>
      <!--
	Inertial parameters from Barrett Technology, Inc, WAM Arm Inertial
	Specifications, 2008, pages 15-16, Document: D1005, Version: AC.02
-->
      <mass value="1.80228141"/>
      <origin xyz="-0.03825858 0.20750770 0.00003309"/>
      <inertia ixx="0.05911077" ixy="-0.00249612" ixz="0.00000738" iyy="0.00324550" iyz="-0.00001767" izz="0.05927043"/>
    </inertial>
    <visual>
      <origin rpy="1.57079632679 0 0" xyz="-0.045 0.55 0.0"/>
      <geometry name="wam_link_3_visual">
        <mesh filename="package://wam_description/meshes/wam3.stl" scale="1.0 1.0 1.0"/>
      </geometry>
      <material name="Grey">
        <color rgba="0.75 0.75 0.75 1.0"/>
      </material>
    </visual>
    <collision>
      <origin rpy="1.57079632679 0 0" xyz="-0.045 0.55 0.0"/>
      <geometry name="wam_link_3_collision">
        <mesh filename="package://wam_description/meshes/wam3.stl" scale="1.0 1.0 1.0"/>
      </geometry>
      <contact_coefficients kd="1.0" kp="1000.0" mu="0"/>
    </collision>
  </link>
  <gazebo reference="wam_link_3">
    <material>Gazebo/White</material>
    <selfCollide>true</selfCollide>
  </gazebo>
  <!-- Virtual joint and link are necessary due to the offset, in
	order to keep the Denavit-Hartenberg convention, as libBarrett and
	the Inertial Specifications uses it.  -->
  <link name="wam_link_3_virtual"/>
  <joint name="wam_joint_3" type="revolute">
    <parent link="wam_link_2"/>
    <child link="wam_link_3_virtual"/>
    <origin rpy="-1.57079632679 0 0" xyz="0.0 0.0 0.55"/>
    <axis xyz="0 -1 0"/>
    <!--
	from Barrett Technology, Inc, WAM Arm User's Manual, 2008, Document:
	D1001, Version: AH.00
	
	lower and upper limits: page 71
	velocity: page 17
	friction: page 71
	effort: cable limit (page 75) x reduction (page 68)
-->
    <limit effort="50.85" lower="-2.8" upper="2.8" velocity="2.0"/>
    <!--dynamics friction="${3.0/7}"/-->
  </joint>
  <joint name="wam_joint_3_virtual" type="fixed">
    <parent link="wam_link_3_virtual"/>
    <child link="wam_link_3"/>
    <origin rpy="0 0 0" xyz="0.045 0.0 0.0"/>
  </joint>
  <transmission name="j3_transmission">
    <type>transmission_interface/SimpleTransmission</type>
    <joint name="wam_joint_3">
      <hardwareInterface>hardware_interface/EffortJointInterface</hardwareInterface>
    </joint>
    <actuator name="j3_motor">
      <mechanicalReduction>28.25</mechanicalReduction>
    </actuator>
  </transmission>
  <link name="wam_link_4">
    <inertial>
      <!--
	Inertial parameters from Barrett Technology, Inc, WAM Arm Inertial
	Specifications, 2008, pages 21-22, Document: D1005, Version: AC.02
-->
      <mass value="2.40016804"/>
      <origin xyz="0.00498512 -0.000022942 0.13271662"/>
      <inertia ixx="0.01491672" ixy="0.00001741" ixz="-0.00150604" iyy="0.01482922" iyz="-0.00002109" izz="0.00294463"/>
    </inertial>
    <visual>
      <origin rpy="-1.57079632679 0 0" xyz="0.045 0.0 0.0"/>
      <geometry name="wam_link_4_visual">
        <mesh filename="package://wam_description/meshes/wam4.stl" scale="1.0 1.0 1.0"/>
      </geometry>
      <material name="Grey">
        <color rgba="0.75 0.75 0.75 1.0"/>
      </material>
    </visual>
    <collision>
      <origin rpy="-1.57079632679 0 0" xyz="0.045 0.0 0.0"/>
      <geometry name="wam_link_4_collision">
        <mesh filename="package://wam_description/meshes/wam4.stl" scale="1.0 1.0 1.0"/>
      </geometry>
      <contact_coefficients kd="1.0" kp="1000.0" mu="0"/>
    </collision>
  </link>
  <gazebo reference="wam_link_4">
    <material>Gazebo/White</material>
    <selfCollide>true</selfCollide>
  </gazebo>
  <!-- Virtual joint and link are necessary due to the offset, in
	order to keep the Denavit-Hartenberg convention, as libBarrett and
	the Inertial Specifications uses it.  -->
  <link name="wam_link_4_virtual"/>
  <joint name="wam_joint_4" type="revolute">
    <parent link="wam_link_3"/>
    <child link="wam_link_4_virtual"/>
    <origin rpy="1.57079632679 0 0" xyz="0.0 0.0 0.0"/>
    <axis xyz="0 1 0"/>
    <!--
	from Barrett Technology, Inc, WAM Arm User's Manual, 2008, Document:
	D1001, Version: AH.00
	
	lower and upper limits: page 71
	velocity: page 17
	friction: page 71
	effort: cable limit (page 75) x reduction (page 68)
-->
    <limit effort="28.8" lower="-0.9" upper="3.1" velocity="2.0"/>
    <!--dynamics friction="${3.0/7}"/-->
  </joint>
  <joint name="wam_joint_4_virtual" type="fixed">
    <parent link="wam_link_4_virtual"/>
    <child link="wam_link_4"/>
    <origin rpy="0 0 0" xyz="-0.045 0.0 0.0"/>
  </joint>
  <transmission name="j4_transmission">
    <type>transmission_interface/SimpleTransmission</type>
    <joint name="wam_joint_4">
      <hardwareInterface>hardware_interface/EffortJointInterface</hardwareInterface>
    </joint>
    <actuator name="j4_motor">
      <mechanicalReduction>1</mechanicalReduction>
    </actuator>
  </transmission>
  <link name="wam_link_5">
    <inertial>
      <!--
	Inertial parameters from Barrett Technology, Inc, WAM Arm Inertial
	Specifications, 2008, pages 23-24, Document: D1005, Version: AC.02
-->
      <mass value="0.12376019"/>
      <origin xyz="0.00008921 0.00511217 0.00435824"/>
      <inertia ixx="0.00005029" ixy="0.00000020" ixz="-0.00000005" iyy="0.00007582" iyz="-0.00000359" izz="0.00006270"/>
    </inertial>
    <visual>
      <origin rpy="1.57079632679 0 0" xyz="0.0 0.0 0.0"/>
      <geometry name="wam_link_5_visual">
        <mesh filename="package://wam_description/meshes/wam5.stl" scale="1.0 1.0 1.0"/>
      </geometry>
      <material name="Grey">
        <color rgba="0.75 0.75 0.75 1.0"/>
      </material>
    </visual>
    <collision>
      <origin rpy="1.57079632679 0 0" xyz="0.0 0.0 0.0"/>
      <geometry name="wam_link_5_collision">
        <mesh filename="package://wam_description/meshes/wam5.stl" scale="1.0 1.0 1.0"/>
      </geometry>
      <contact_coefficients kd="1.0" kp="1000.0" mu="0"/>
    </collision>
  </link>
  <gazebo reference="wam_link_5">
    <material>Gazebo/White</material>
    <selfCollide>true</selfCollide>
  </gazebo>
  <joint name="wam_joint_5" type="revolute">
    <parent link="wam_link_4"/>
    <child link="wam_link_5"/>
    <origin rpy="-1.57079632679 0 0" xyz="0.0 0.0 0.3"/>
    <axis xyz="0 -1 0"/>
    <!--
	from Barrett Technology, Inc, WAM Arm User's Manual, 2008, Document:
	D1001, Version: AH.00
	
	lower and upper limits: page 71
	velocity: page 17
	friction: page 71
	effort: cable limit (page 75) x reduction (page 68)
-->
    <limit effort="5.688" lower="-4.76" upper="1.24" velocity="2.0"/>
    <!--dynamics friction="${3.0/7}"/-->
  </joint>
  <transmission name="j5_transmission">
    <type>transmission_interface/SimpleTransmission</type>
    <joint name="wam_joint_5">
      <hardwareInterface>hardware_interface/EffortJointInterface</hardwareInterface>
    </joint>
    <actuator name="j5_motor">
      <mechanicalReduction>9.48</mechanicalReduction>
    </actuator>
  </transmission>
  <link name="wam_link_6">
    <inertial>
      <!--
	Inertial parameters from Barrett Technology, Inc, WAM Arm Inertial
	Specifications, 2008, pages 25-26, Document: D1005, Version: AC.02
-->
      <mass value="0.41797364"/>
      <origin xyz="-0.00012262 -0.01703194 0.02468336"/>
      <inertia ixx="0.00055516" ixy="0.00000061" ixz="-0.00000074" iyy="0.00024367" iyz="-0.00004590" izz="0.00045358"/>
    </inertial>
    <visual>
      <origin rpy="-1.57079632679 0 0" xyz="0.0 0.0 0.0"/>
      <geometry name="wam_link_6_visual">
        <mesh filename="package://wam_description/meshes/wam6.stl" scale="1.0 1.0 1.0"/>
      </geometry>
      <material name="Grey">
        <color rgba="0.75 0.75 0.75 1.0"/>
      </material>
    </visual>
    <collision>
      <origin rpy="-1.57079632679 0 0" xyz="0.0 0.0 0.0"/>
      <geometry name="wam_link_6_collision">
        <mesh filename="package://wam_description/meshes/wam6.stl" scale="1.0 1.0 1.0"/>
      </geometry>
      <contact_coefficients kd="1.0" kp="1000.0" mu="0"/>
    </collision>
  </link>
  <gazebo reference="wam_link_6">
    <material>Gazebo/White</material>
    <selfCollide>true</selfCollide>
  </gazebo>
  <joint name="wam_joint_6" type="revolute">
    <parent link="wam_link_5"/>
    <child link="wam_link_6"/>
    <origin rpy="1.57079632679 0 0" xyz="0.0 0.0 0.0"/>
    <axis xyz="0 1 0"/>
    <!--
	from Barrett Technology, Inc, WAM Arm User's Manual, 2008, Document:
	D1001, Version: AH.00
	
	lower and upper limits: page 71
	velocity: page 17
	friction: page 71
	effort: cable limit (page 75) x reduction (page 68)
-->
    <limit effort="5.688" lower="-1.57079632679" upper="1.57079632679" velocity="2.0"/>
    <!--dynamics friction="${3.0/7}"/-->
  </joint>
  <transmission name="j6_transmission">
    <type>transmission_interface/SimpleTransmission</type>
    <joint name="wam_joint_6">
      <hardwareInterface>hardware_interface/EffortJointInterface</hardwareInterface>
    </joint>
    <actuator name="j6_motor">
      <mechanicalReduction>9.48</mechanicalReduction>
    </actuator>
  </transmission>
  <link name="wam_link_7">
    <inertial>
      <!--
	Inertial parameters from Barrett Technology, Inc, WAM Arm Inertial
	Specifications, 2008, pages 27-28, Document: D1005, Version: AC.02
-->
      <mass value="0.06864753"/>
      <origin xyz="-0.00007974 0.00016313 -0.00323552"/>
      <inertia ixx="0.00003773" ixy="-0.00000019" ixz="0.00000000" iyy="0.00003806" iyz="-0.00000000" izz="0.00007408"/>
    </inertial>
    <visual>
      <origin rpy="0 0 0" xyz="0.0 0.0 -0.06"/>
      <geometry name="wam_link_7_visual">
        <mesh filename="package://wam_description/meshes/wam7.stl" scale="1.0 1.0 1.0"/>
      </geometry>
      <material name="Grey">
        <color rgba="0.75 0.75 0.75 1.0"/>
      </material>
    </visual>
    <collision>
      <origin rpy="0 0 0" xyz="0.0 0.0 -0.06"/>
      <geometry name="wam_link_7_collision">
        <mesh filename="package://wam_description/meshes/wam7.stl" scale="1.0 1.0 1.0"/>
      </geometry>
      <contact_coefficients kd="1.0" kp="1000.0" mu="0"/>
    </collision>
  </link>
  <gazebo reference="wam_link_7">
    <material>Gazebo/White</material>
    <selfCollide>true</selfCollide>
  </gazebo>
  <joint name="wam_joint_7" type="revolute">
    <parent link="wam_link_6"/>
    <child link="wam_link_7"/>
    <origin rpy="0 0 0" xyz="0.0 0.0 0.06"/>
    <axis xyz="0 0 1"/>
    <!--
	from Barrett Technology, Inc, WAM Arm User's Manual, 2008, Document:
	D1001, Version: AH.00
	
	lower and upper limits: page 71
	velocity: page 17
	friction: page 71
	effort: cable limit (page 75) x reduction (page 68)
-->
    <limit effort="9.15209" lower="-3.0" upper="3.0" velocity="2.0"/>
    <!--dynamics friction="${3.0/7}"/-->
  </joint>
  <transmission name="j7_transmission">
    <type>transmission_interface/SimpleTransmission</type>
    <joint name="wam_joint_7">
      <hardwareInterface>hardware_interface/EffortJointInterface</hardwareInterface>
    </joint>
    <actuator name="j7_motor">
      <mechanicalReduction>14.93</mechanicalReduction>
    </actuator>
  </transmission>
  <link name="wam_tool_plate"/>
  <joint name="wam_tool_plate_joint" type="fixed">
    <parent link="wam_link_7"/>
    <child link="wam_tool_plate"/>
    <origin rpy="0 0 0" xyz="0.0 0.0 0.0"/>
  </joint>
  <gazebo>
    <plugin filename="libgazebo_ros_control.so" name="gazebo_ros_control">
      <!--robotNamespace>wam</robotNamespace-->
      <!-- Custom plugin -->
      <!-- robotSimType>wam_gazebo_ros_control/WamRobotHWSim</robotSimType -->
      <!-- Default plugin -->
      <!-- robotSimType>gazebo_ros_control/DefaultRobotHWSim</robotSimType -->
      <controlPeriod>0.001</controlPeriod>
    </plugin>
  </gazebo>
  <joint name="platform_wam_joint" type="fixed">
    <parent link="platform_top_link"/>
    <child link="wam_origin"/>
    <origin rpy="1.57079632679 0 1.57079632679" xyz="0.05 -0.22 -0.14"/>
  </joint>
</robot>

